Workbook

Sheet Sheet1
A1: No. | B1: Meaning | C1: Default | D1: Pinion test
A2: P01 | B2: Type of movement | C2: 0 | D2: 1
B3: 0 = rotational
B4: Rotating table, 1 limit switch for mechanical zero
B5: (referencing)
B6: 1 = linear for XY tables or other linear systems, 2 limit switches:
B7: Mechanical zero and limit direction – Limit direction +
A8: P02 | B8: Measuring units of movement | C8: 1 | D8: =Sheet2!E17 -> 2
B9: 1 = step
B10: 2 = mm
B11: 3 = inch
B12: 4 = degree
A13: P03 | B13: Conversion factor for the thread 1 step corresponds to ... | C13: 1 | D13: =Sheet2!E22 -> 0.0050131798
B14: If P03 = 1 (steps) the conversion factor is 1.
B15: Computing the conversion factor:
B16: Thread
B17: Conversion factor =
B19: Numberof stepsperrevolution
B20: Example:
B21: 4 mm thread pitch
B22: 200-step motor = 400 steps/rev. in the half step mode
B23: Conversion factor =
B24: = 0.01
A25: P04 | B25: Start/stop frequency | C25: 400 | D25: =Sheet2!E23 -> 943
B26: The start/stop frequency is the maximum frequency to start or stop the motor without ramp. At higher frequencies, step losses or motor stop would be the result of a start or stop without ramp. The start/stop frequency depends on various factors: type of motor, load, mechanical system, power stage.
B27: The frequency is programmed in Hz.
A28: P05 | B28: not used
A29: P06
A30: P07 | B30: Emergency stop ramp | C30: 100 000 | D30: =Sheet2!E24 -> 20000
B31: The frequency is programmed in 4000-Hz/sec-steps.
A32: P08 | B32: fmax MØP (mechanical zero point) | C32: 4000 | D32: =Sheet2!E25 -> 94
B33: Run frequency during initializing (referencing)
B34: Enter in Hz (integer value)
A35: P09 | B35: Ramp MØP | C35: 4000 | D35: =Sheet2!E28 -> 0
B36: Ramp during initializing, associated to parameter P08 Enter in 4000-Hz/sec-steps
A37: P10 | B37: fmin MØP Run frequency for leaving the limit switch range | C37: 400 | D37: =Sheet2!E29 -> 943
B38: Enter in Hz
A39: P11 | B39: MØP offset for limit switch direction + | C39: 0 | D39: =Sheet2!E30 -> 2?
B40: Distance between reference point MØP and limit switch activation
B41: Unit: is defined in parameter P02
...

Sheet Sheet2
C3: Test parameters (fixed) | D3: Value | E3: Input in controller | F3: Unit | G3: Control parameter | H3: Comment
C4: Gear ratio wheel -> pinion | D4: 42 | F4: [-]
C5: Angular acceleration required | D5: 2.6731253 | F5: [rad/s2]
C6: Angular acceleration required | D6: =D5/(2*PI()) -> 0.42544111 | F6: [rot/s2]
C7: Drive speed of pinion | D7: 30.1 | F7: [rpm]
C8: Operational speed | D8: 47.280969 | F8: [mm/s]
C9: Rotations per cycle | D9: 3.1830989
C10: Stroke of gear rack | D10: 150 | F10: [mm]
C11: Reference diameter pinion | D11: 30 | F11: [mm]
C12: Stroke per rotation of pinion | D12: =2*PI()*(D11/2) -> 94.24778 | F12: [mm]
C13: Rotations per full stroke | D13: =D10/D12 -> 1.5915494 | F13: [-]
C14: Rotations per cycle | D14: =2*D13 -> 3.1830989 | F14: [-]
C15: Drive speed of pinion | D15: =D8/D12 -> 0.50166667 | F15: [rot/s]
C16: Motor controller parameters
C17: Measuring units of movement | D17: 2 | E17: =D17 -> 2 | F17: [mm] | G17: P02
C18: Full steps per revolution | D18: 200 | F18: [-/rot]
C19: Step resolution | D19: 94 | E19: =D19 -> 94 | F19: [-] | G19: P45
C20: Pulses/steps per revolution | D20: =D18*D19 -> 18800 | F20: [-/rot]
C21: thread pitch | D21: =D12 -> 94.24778 | F21: [mm] | H21: Thread pitch: displacement per single rotation of thread.
C22: Conversion factor for the thread | D22: =D21/D20 -> 0.0050131798 | E22: =D22 -> 0.0050131798 | F22: [-] | G22: P03 | H22: Motor controller sees the system as a worm wheel.
C23: Start/stop frequency | D23: =D33/10 -> 943.13333 | E23: =ROUND(D23,0) -> 943 | F23: [Hz] | G23: P04
C24: Stop ramp down frequency | D24: =20*D23 -> 18862.667 | E24: =MROUND(D24,4000) -> 20000 | F24: [Hz/s] | G24: P07 | H24: Should be an integer multiple of 4000
C25: Pulse frequency during initializing | D25: =D23/10 -> 94.313333 | E25: =ROUND(D25,0) -> 94 | F25: [Hz] | G25: P08
C26: Pulse rampup frequency when running | D26: =D6*D20 -> 7998.2928 | E26: =MROUND(D26,4000) -> 8000 | F26: Hz/s] | H26: Should be an integer multiple of 4000
C27: Rampup time | D27: 1 | F27: [s]
C28: Ramp up when initializing | D28: =D25*D27 -> 94.313333 | E28: =MROUND(D28,4000) -> 0 | F28: [Hz/s] | G28: P09 | H28: Should be an integer multiple of 4000
C29: Frequeny for leaving limit switch range | D29: =D33/10 -> 943.13333 | E29: =ROUND(D29,0) -> 943 | F29: [Hz] | G29: P10
C30: MØP offset for limit switch direction + Distance between reference point MØP and limit switch activation | D30: 2? | E30: =D30 -> 2? | F30: =F17 -> [mm] | G30: P11
C31: MØP offset for limit switch direction – Distance between reference point MØP and limit switch activation Unit: is defined in parameter P02 | D31: 2? | E31: =D31 -> 2? | F31: =F17 -> [mm] | G31: P12
C32: Recovery time M0, time lapse during initialization | D32: 20 | E32: =D32 -> 20 | F32: [ms] | G32: P13 | H32: Used default value of 20 msec
C33: Run frequency during program operation | D33: =D15*D20 -> 9431.3333 | E33: =ROUND(D33,0) -> 9431 | F33: [Hz] | G33: P14
C34: Ramp for run frequency | D34: =D6*D20 -> 7998.2928 | E34: =MROUND(D34,4000) -> 8000 | F34: [Hz/s] | G34: P15 | H34: Should be an integer multiple of 4000
C35: Recovery time after positioning | D35: 20 | E35: =D35 -> 20 | F35: [ms] | G35: P16 | H35: Used default value of 20 msec
